2025-03-01 17:34:41,205 ERROR: Exception on /devices [GET] [in C:\Users\28637\AppData\Local\Programs\Python\Python311\Lib\site-packages\flask\app.py:1414]
Traceback (most recent call last):
  File "C:\Users\28637\AppData\Local\Programs\Python\Python311\Lib\site-packages\flask\app.py", line 2190, in wsgi_app
    response = self.full_dispatch_request()
               ^^^^^^^^^^^^^^^^^^^^^^^^^^^^
  File "C:\Users\28637\AppData\Local\Programs\Python\Python311\Lib\site-packages\flask\app.py", line 1486, in full_dispatch_request
    rv = self.handle_user_exception(e)
         ^^^^^^^^^^^^^^^^^^^^^^^^^^^^^
  File "C:\Users\28637\AppData\Local\Programs\Python\Python311\Lib\site-packages\flask\app.py", line 1484, in full_dispatch_request
    rv = self.dispatch_request()
         ^^^^^^^^^^^^^^^^^^^^^^^
  File "C:\Users\28637\AppData\Local\Programs\Python\Python311\Lib\site-packages\flask\app.py", line 1469, in dispatch_request
    return self.ensure_sync(self.view_functions[rule.endpoint])(**view_args)
           ^^^^^^^^^^^^^^^^^^^^^^^^^^^^^^^^^^^^^^^^^^^^^^^^^^^^^^^^^^^^^^^^^
  File "C:\Users\28637\AppData\Local\Programs\Python\Python311\Lib\site-packages\flask_login\utils.py", line 290, in decorated_view
    return current_app.ensure_sync(func)(*args, **kwargs)
           ^^^^^^^^^^^^^^^^^^^^^^^^^^^^^^^^^^^^^^^^^^^^^^
  File "C:\Users\28637\Desktop\demo1\实例3\app.py", line 107, in devices
    return render_template('devices.html', title='设备管理', devices=all_devices)
           ^^^^^^^^^^^^^^^^^^^^^^^^^^^^^^^^^^^^^^^^^^^^^^^^^^^^^^^^^^^^^^^^^^
  File "C:\Users\28637\AppData\Local\Programs\Python\Python311\Lib\site-packages\flask\templating.py", line 151, in render_template
    return _render(app, template, context)
           ^^^^^^^^^^^^^^^^^^^^^^^^^^^^^^^
  File "C:\Users\28637\AppData\Local\Programs\Python\Python311\Lib\site-packages\flask\templating.py", line 132, in _render
    rv = template.render(context)
         ^^^^^^^^^^^^^^^^^^^^^^^^
  File "C:\Users\28637\AppData\Local\Programs\Python\Python311\Lib\site-packages\jinja2\environment.py", line 1301, in render
    self.environment.handle_exception()
  File "C:\Users\28637\AppData\Local\Programs\Python\Python311\Lib\site-packages\jinja2\environment.py", line 936, in handle_exception
    raise rewrite_traceback_stack(source=source)
  File "C:\Users\28637\Desktop\demo1\实例3\templates\devices.html", line 1, in top-level template code
    {% extends "base.html" %}
  File "C:\Users\28637\Desktop\demo1\实例3\templates\base.html", line 66, in top-level template code
    <a class="nav-link {% if request.path == url_for('settings') %}active{% endif %}" href="{{ url_for('settings') }}">
    ^^^^^^^^^^^^^^^^^^^^^^^^^
  File "C:\Users\28637\AppData\Local\Programs\Python\Python311\Lib\site-packages\flask\app.py", line 1697, in url_for
    return self.handle_url_build_error(error, endpoint, values)
           ^^^^^^^^^^^^^^^^^^^^^^^^^^^^^^^^^^^^^^^^^^^^^^^^^^^^
  File "C:\Users\28637\AppData\Local\Programs\Python\Python311\Lib\site-packages\flask\app.py", line 1686, in url_for
    rv = url_adapter.build(  # type: ignore[union-attr]
         ^^^^^^^^^^^^^^^^^^^^^^^^^^^^^^^^^^^^^^^^^^^^^^
  File "C:\Users\28637\AppData\Local\Programs\Python\Python311\Lib\site-packages\werkzeug\routing\map.py", line 950, in build
    raise BuildError(endpoint, values, method, self)
werkzeug.routing.exceptions.BuildError: Could not build url for endpoint 'settings'. Did you mean 'static' instead?
2025-03-01 17:34:46,622 ERROR: Exception on /network_analysis [GET] [in C:\Users\28637\AppData\Local\Programs\Python\Python311\Lib\site-packages\flask\app.py:1414]
Traceback (most recent call last):
  File "C:\Users\28637\AppData\Local\Programs\Python\Python311\Lib\site-packages\flask\app.py", line 2190, in wsgi_app
    response = self.full_dispatch_request()
               ^^^^^^^^^^^^^^^^^^^^^^^^^^^^
  File "C:\Users\28637\AppData\Local\Programs\Python\Python311\Lib\site-packages\flask\app.py", line 1486, in full_dispatch_request
    rv = self.handle_user_exception(e)
         ^^^^^^^^^^^^^^^^^^^^^^^^^^^^^
  File "C:\Users\28637\AppData\Local\Programs\Python\Python311\Lib\site-packages\flask\app.py", line 1484, in full_dispatch_request
    rv = self.dispatch_request()
         ^^^^^^^^^^^^^^^^^^^^^^^
  File "C:\Users\28637\AppData\Local\Programs\Python\Python311\Lib\site-packages\flask\app.py", line 1469, in dispatch_request
    return self.ensure_sync(self.view_functions[rule.endpoint])(**view_args)
           ^^^^^^^^^^^^^^^^^^^^^^^^^^^^^^^^^^^^^^^^^^^^^^^^^^^^^^^^^^^^^^^^^
  File "C:\Users\28637\AppData\Local\Programs\Python\Python311\Lib\site-packages\flask_login\utils.py", line 290, in decorated_view
    return current_app.ensure_sync(func)(*args, **kwargs)
           ^^^^^^^^^^^^^^^^^^^^^^^^^^^^^^^^^^^^^^^^^^^^^^
  File "C:\Users\28637\Desktop\demo1\实例3\app.py", line 779, in network_analysis
    return render_template('network_analysis.html',
          ^^^^^^^^^^^^^^^^^^^^^^^^^^^^^^^^^^^^^^^^^
  File "C:\Users\28637\AppData\Local\Programs\Python\Python311\Lib\site-packages\flask\templating.py", line 151, in render_template
    return _render(app, template, context)
           ^^^^^^^^^^^^^^^^^^^^^^^^^^^^^^^
  File "C:\Users\28637\AppData\Local\Programs\Python\Python311\Lib\site-packages\flask\templating.py", line 132, in _render
    rv = template.render(context)
         ^^^^^^^^^^^^^^^^^^^^^^^^
  File "C:\Users\28637\AppData\Local\Programs\Python\Python311\Lib\site-packages\jinja2\environment.py", line 1301, in render
    self.environment.handle_exception()
  File "C:\Users\28637\AppData\Local\Programs\Python\Python311\Lib\site-packages\jinja2\environment.py", line 936, in handle_exception
    raise rewrite_traceback_stack(source=source)
  File "C:\Users\28637\Desktop\demo1\实例3\templates\network_analysis.html", line 1, in top-level template code
    {% extends "base.html" %}
  File "C:\Users\28637\Desktop\demo1\实例3\templates\base.html", line 66, in top-level template code
    <a class="nav-link {% if request.path == url_for('settings') %}active{% endif %}" href="{{ url_for('settings') }}">
    ^^^^^^^^^^^^^^^^^^^^^^^^^
  File "C:\Users\28637\AppData\Local\Programs\Python\Python311\Lib\site-packages\flask\app.py", line 1697, in url_for
    return self.handle_url_build_error(error, endpoint, values)
           ^^^^^^^^^^^^^^^^^^^^^^^^^^^^^^^^^^^^^^^^^^^^^^^^^^^^
  File "C:\Users\28637\AppData\Local\Programs\Python\Python311\Lib\site-packages\flask\app.py", line 1686, in url_for
    rv = url_adapter.build(  # type: ignore[union-attr]
         ^^^^^^^^^^^^^^^^^^^^^^^^^^^^^^^^^^^^^^^^^^^^^^
  File "C:\Users\28637\AppData\Local\Programs\Python\Python311\Lib\site-packages\werkzeug\routing\map.py", line 950, in build
    raise BuildError(endpoint, values, method, self)
werkzeug.routing.exceptions.BuildError: Could not build url for endpoint 'settings'. Did you mean 'static' instead?
2025-03-01 17:34:57,432 INFO: 网络监控平台启动 [in C:\Users\28637\Desktop\demo1\实例3\app.py:44]
2025-03-01 17:34:57,450 INFO: 数据收集后台任务启动 [in C:\Users\28637\Desktop\demo1\实例3\app.py:816]
2025-03-01 17:34:58,266 INFO: 网络监控平台启动 [in C:\Users\28637\Desktop\demo1\实例3\app.py:44]
2025-03-01 17:34:58,285 INFO: 数据收集后台任务启动 [in C:\Users\28637\Desktop\demo1\实例3\app.py:816]
2025-03-01 17:36:24,752 INFO: 网络监控平台启动 [in C:\Users\28637\Desktop\demo1\实例3\app.py:44]
2025-03-01 17:36:24,771 INFO: 数据收集后台任务启动 [in C:\Users\28637\Desktop\demo1\实例3\app.py:818]
2025-03-01 17:36:34,813 INFO: 网络监控平台启动 [in C:\Users\28637\Desktop\demo1\实例3\app.py:44]
2025-03-01 17:36:34,833 INFO: 数据收集后台任务启动 [in C:\Users\28637\Desktop\demo1\实例3\app.py:818]
2025-03-01 17:37:56,480 ERROR: 数据收集出错: 'NoneType' object is not subscriptable [in C:\Users\28637\Desktop\demo1\实例3\app.py:861]
2025-03-01 17:38:44,431 ERROR: 数据收集出错: (sqlite3.OperationalError) database is locked
[SQL: INSERT INTO alert (device_id, timestamp, alert_type, message, severity, resolved, resolved_time, resolved_by, resolution_notes) VALUES (?, ?, ?, ?, ?, ?, ?, ?, ?) RETURNING id]
[parameters: (1, 1740821819.64213, 'high_packet_loss', '设备 核心交换机 (192.168.1.1) 丢包率过高: 7.8% > 5%', 'warning', 0, None, None, None)]
(Background on this error at: https://sqlalche.me/e/20/e3q8) [in C:\Users\28637\Desktop\demo1\实例3\app.py:863]
2025-03-01 17:38:51,349 ERROR: 数据收集出错: 'NoneType' object is not subscriptable [in C:\Users\28637\Desktop\demo1\实例3\app.py:861]
2025-03-01 17:39:14,434 ERROR: 数据收集出错: This Session's transaction has been rolled back due to a previous exception during flush. To begin a new transaction with this Session, first issue Session.rollback(). Original exception was: (sqlite3.OperationalError) database is locked
[SQL: INSERT INTO alert (device_id, timestamp, alert_type, message, severity, resolved, resolved_time, resolved_by, resolution_notes) VALUES (?, ?, ?, ?, ?, ?, ?, ?, ?) RETURNING id]
[parameters: (1, 1740821819.64213, 'high_packet_loss', '设备 核心交换机 (192.168.1.1) 丢包率过高: 7.8% > 5%', 'warning', 0, None, None, None)]
(Background on this error at: https://sqlalche.me/e/20/e3q8) (Background on this error at: https://sqlalche.me/e/20/7s2a) [in C:\Users\28637\Desktop\demo1\实例3\app.py:863]
2025-03-01 17:39:29,709 INFO: 网络监控平台启动 [in C:\Users\28637\Desktop\demo1\实例3\app.py:44]
2025-03-01 17:39:29,729 INFO: 数据收集后台任务启动 [in C:\Users\28637\Desktop\demo1\实例3\app.py:854]
2025-03-01 17:39:46,156 ERROR: 数据收集出错: 'NoneType' object is not subscriptable [in C:\Users\28637\Desktop\demo1\实例3\app.py:861]
2025-03-01 17:41:02,301 INFO: 网络监控平台启动 [in C:\Users\28637\Desktop\demo1\实例3\app.py:44]
2025-03-01 17:41:02,319 INFO: 数据收集后台任务启动 [in C:\Users\28637\Desktop\demo1\实例3\app.py:862]
2025-03-01 17:41:16,395 INFO: 网络监控平台启动 [in C:\Users\28637\Desktop\demo1\实例3\app.py:45]
2025-03-01 17:41:16,414 INFO: 数据收集后台任务启动 [in C:\Users\28637\Desktop\demo1\实例3\app.py:863]
