2025-03-01 16:17:37,385 ERROR: 数据收集出错: (sqlite3.OperationalError) database is locked
[SQL: INSERT INTO alert (device_id, timestamp, alert_type, message, severity, resolved, resolved_time, resolved_by, resolution_notes) VALUES (?, ?, ?, ?, ?, ?, ?, ?, ?) RETURNING id]
[parameters: (1, 1740816952.467727, 'high_packet_loss', '设备 核心交换机 (192.168.1.1) 丢包率过高: 9.4% > 5%', 'warning', 0, None, None, None)]
(Background on this error at: https://sqlalche.me/e/20/e3q8) [in C:\Users\28637\Desktop\demo1\实例3\app.py:252]
2025-03-01 16:17:38,158 ERROR: 数据收集出错: This Session's transaction has been rolled back due to a previous exception during flush. To begin a new transaction with this Session, first issue Session.rollback(). Original exception was: (raised as a result of Query-invoked autoflush; consider using a session.no_autoflush block if this flush is occurring prematurely)
(sqlite3.OperationalError) database is locked
[SQL: INSERT INTO alert (device_id, timestamp, alert_type, message, severity, resolved, resolved_time, resolved_by, resolution_notes) VALUES (?, ?, ?, ?, ?, ?, ?, ?, ?)]
[parameters: (1, 1740816793.08973, 'high_latency', '设备 核心交换机 (192.168.1.1) 延迟过高: 184.0ms > 100ms', 'warning', 0, None, None, None)]
(Background on this error at: https://sqlalche.me/e/20/e3q8) (Background on this error at: https://sqlalche.me/e/20/7s2a) [in C:\Users\28637\Desktop\demo1\实例3\app.py:252]
2025-03-01 16:17:40,736 ERROR: 数据收集出错: This Session's transaction has been rolled back due to a previous exception during flush. To begin a new transaction with this Session, first issue Session.rollback(). Original exception was: (sqlite3.OperationalError) database is locked
[SQL: INSERT INTO alert (device_id, timestamp, alert_type, message, severity, resolved, resolved_time, resolved_by, resolution_notes) VALUES (?, ?, ?, ?, ?, ?, ?, ?, ?) RETURNING id]
[parameters: (2, 1740816860.926593, 'high_packet_loss', '设备 边界路由器 (192.168.1.2) 丢包率过高: 5.8% > 5%', 'warning', 0, None, None, None)]
(Background on this error at: https://sqlalche.me/e/20/e3q8) (Background on this error at: https://sqlalche.me/e/20/7s2a) [in C:\Users\28637\Desktop\demo1\实例3\app.py:252]
2025-03-01 16:17:41,504 ERROR: 数据收集出错: This Session's transaction has been rolled back due to a previous exception during flush. To begin a new transaction with this Session, first issue Session.rollback(). Original exception was: (sqlite3.OperationalError) database is locked
[SQL: INSERT INTO alert (device_id, timestamp, alert_type, message, severity, resolved, resolved_time, resolved_by, resolution_notes) VALUES (?, ?, ?, ?, ?, ?, ?, ?, ?) RETURNING id]
[parameters: (2, 1740816861.668941, 'high_packet_loss', '设备 边界路由器 (192.168.1.2) 丢包率过高: 6.0% > 5%', 'warning', 0, None, None, None)]
(Background on this error at: https://sqlalche.me/e/20/e3q8) (Background on this error at: https://sqlalche.me/e/20/7s2a) [in C:\Users\28637\Desktop\demo1\实例3\app.py:252]
2025-03-01 16:18:50,500 INFO: 网络监控平台启动 [in C:\Users\28637\Desktop\demo1\实例3\app.py:42]
2025-03-01 16:18:50,514 INFO: 数据收集后台任务启动 [in C:\Users\28637\Desktop\demo1\实例3\app.py:200]
2025-03-01 16:18:51,205 INFO: 网络监控平台启动 [in C:\Users\28637\Desktop\demo1\实例3\app.py:42]
2025-03-01 16:18:51,218 INFO: 数据收集后台任务启动 [in C:\Users\28637\Desktop\demo1\实例3\app.py:200]
2025-03-01 16:21:49,660 ERROR: 数据收集出错: 'NoneType' object is not subscriptable [in C:\Users\28637\Desktop\demo1\实例3\app.py:245]
2025-03-01 16:22:15,320 ERROR: 数据收集出错: 'NoneType' object is not subscriptable [in C:\Users\28637\Desktop\demo1\实例3\app.py:245]
2025-03-01 16:22:44,446 ERROR: 数据收集出错: 'NoneType' object is not subscriptable [in C:\Users\28637\Desktop\demo1\实例3\app.py:245]
2025-03-01 16:22:50,807 ERROR: 数据收集出错: (raised as a result of Query-invoked autoflush; consider using a session.no_autoflush block if this flush is occurring prematurely)
(sqlite3.OperationalError) database is locked
[SQL: INSERT INTO network_data (device_id, timestamp, cpu_usage, memory_usage, bandwidth_usage, packet_loss, latency, interface_status, system_uptime, error_count) VALUES (?, ?, ?, ?, ?, ?, ?, ?, ?, ?) RETURNING id]
[parameters: (1, 1740817310.558164, 0.0, 0.0, 0.0, 2.9104767066352655, 16.639049405381314, None, None, 0)]
(Background on this error at: https://sqlalche.me/e/20/e3q8) [in C:\Users\28637\Desktop\demo1\实例3\app.py:245]
2025-03-01 16:23:20,807 ERROR: 数据收集出错: This Session's transaction has been rolled back due to a previous exception during flush. To begin a new transaction with this Session, first issue Session.rollback(). Original exception was: (raised as a result of Query-invoked autoflush; consider using a session.no_autoflush block if this flush is occurring prematurely)
(sqlite3.OperationalError) database is locked
[SQL: INSERT INTO network_data (device_id, timestamp, cpu_usage, memory_usage, bandwidth_usage, packet_loss, latency, interface_status, system_uptime, error_count) VALUES (?, ?, ?, ?, ?, ?, ?, ?, ?, ?) RETURNING id]
[parameters: (1, 1740817310.558164, 0.0, 0.0, 0.0, 2.9104767066352655, 16.639049405381314, None, None, 0)]
(Background on this error at: https://sqlalche.me/e/20/e3q8) (Background on this error at: https://sqlalche.me/e/20/7s2a) [in C:\Users\28637\Desktop\demo1\实例3\app.py:245]
2025-03-01 16:23:39,247 ERROR: 数据收集出错: 'NoneType' object is not subscriptable [in C:\Users\28637\Desktop\demo1\实例3\app.py:245]
2025-03-01 16:23:50,809 ERROR: 数据收集出错: This Session's transaction has been rolled back due to a previous exception during flush. To begin a new transaction with this Session, first issue Session.rollback(). Original exception was: (raised as a result of Query-invoked autoflush; consider using a session.no_autoflush block if this flush is occurring prematurely)
(sqlite3.OperationalError) database is locked
[SQL: INSERT INTO network_data (device_id, timestamp, cpu_usage, memory_usage, bandwidth_usage, packet_loss, latency, interface_status, system_uptime, error_count) VALUES (?, ?, ?, ?, ?, ?, ?, ?, ?, ?) RETURNING id]
[parameters: (1, 1740817310.558164, 0.0, 0.0, 0.0, 2.9104767066352655, 16.639049405381314, None, None, 0)]
(Background on this error at: https://sqlalche.me/e/20/e3q8) (Background on this error at: https://sqlalche.me/e/20/7s2a) [in C:\Users\28637\Desktop\demo1\实例3\app.py:245]
2025-03-01 16:24:20,810 ERROR: 数据收集出错: This Session's transaction has been rolled back due to a previous exception during flush. To begin a new transaction with this Session, first issue Session.rollback(). Original exception was: (raised as a result of Query-invoked autoflush; consider using a session.no_autoflush block if this flush is occurring prematurely)
(sqlite3.OperationalError) database is locked
[SQL: INSERT INTO network_data (device_id, timestamp, cpu_usage, memory_usage, bandwidth_usage, packet_loss, latency, interface_status, system_uptime, error_count) VALUES (?, ?, ?, ?, ?, ?, ?, ?, ?, ?) RETURNING id]
[parameters: (1, 1740817310.558164, 0.0, 0.0, 0.0, 2.9104767066352655, 16.639049405381314, None, None, 0)]
(Background on this error at: https://sqlalche.me/e/20/e3q8) (Background on this error at: https://sqlalche.me/e/20/7s2a) [in C:\Users\28637\Desktop\demo1\实例3\app.py:245]
2025-03-01 16:24:34,017 ERROR: 数据收集出错: 'NoneType' object is not subscriptable [in C:\Users\28637\Desktop\demo1\实例3\app.py:245]
2025-03-01 16:24:50,811 ERROR: 数据收集出错: This Session's transaction has been rolled back due to a previous exception during flush. To begin a new transaction with this Session, first issue Session.rollback(). Original exception was: (raised as a result of Query-invoked autoflush; consider using a session.no_autoflush block if this flush is occurring prematurely)
(sqlite3.OperationalError) database is locked
[SQL: INSERT INTO network_data (device_id, timestamp, cpu_usage, memory_usage, bandwidth_usage, packet_loss, latency, interface_status, system_uptime, error_count) VALUES (?, ?, ?, ?, ?, ?, ?, ?, ?, ?) RETURNING id]
[parameters: (1, 1740817310.558164, 0.0, 0.0, 0.0, 2.9104767066352655, 16.639049405381314, None, None, 0)]
(Background on this error at: https://sqlalche.me/e/20/e3q8) (Background on this error at: https://sqlalche.me/e/20/7s2a) [in C:\Users\28637\Desktop\demo1\实例3\app.py:245]
2025-03-01 16:25:20,812 ERROR: 数据收集出错: This Session's transaction has been rolled back due to a previous exception during flush. To begin a new transaction with this Session, first issue Session.rollback(). Original exception was: (raised as a result of Query-invoked autoflush; consider using a session.no_autoflush block if this flush is occurring prematurely)
(sqlite3.OperationalError) database is locked
[SQL: INSERT INTO network_data (device_id, timestamp, cpu_usage, memory_usage, bandwidth_usage, packet_loss, latency, interface_status, system_uptime, error_count) VALUES (?, ?, ?, ?, ?, ?, ?, ?, ?, ?) RETURNING id]
[parameters: (1, 1740817310.558164, 0.0, 0.0, 0.0, 2.9104767066352655, 16.639049405381314, None, None, 0)]
(Background on this error at: https://sqlalche.me/e/20/e3q8) (Background on this error at: https://sqlalche.me/e/20/7s2a) [in C:\Users\28637\Desktop\demo1\实例3\app.py:245]
2025-03-01 16:32:02,589 INFO: 网络监控平台启动 [in C:\Users\28637\Desktop\demo1\实例3\app.py:42]
2025-03-01 16:32:02,610 INFO: 数据收集后台任务启动 [in C:\Users\28637\Desktop\demo1\实例3\app.py:200]
2025-03-01 16:32:03,257 INFO: 网络监控平台启动 [in C:\Users\28637\Desktop\demo1\实例3\app.py:42]
2025-03-01 16:32:03,275 INFO: 数据收集后台任务启动 [in C:\Users\28637\Desktop\demo1\实例3\app.py:200]
2025-03-01 16:35:26,522 ERROR: 数据收集出错: 'NoneType' object is not subscriptable [in C:\Users\28637\Desktop\demo1\实例3\app.py:245]
2025-03-01 16:35:27,107 ERROR: 数据收集出错: 'NoneType' object is not subscriptable [in C:\Users\28637\Desktop\demo1\实例3\app.py:245]
2025-03-01 16:35:59,378 INFO: 网络监控平台启动 [in C:\Users\28637\Desktop\demo1\实例3\app.py:42]
2025-03-01 16:35:59,394 INFO: 数据收集后台任务启动 [in C:\Users\28637\Desktop\demo1\实例3\app.py:307]
